<?xml version="1.0" ?>

<robot name="sq2_ccv" xmlns:xacro="http://ros.org/wiki/xacro">

<!-- foot print to base link -->
    <link name="base_footprint"/>

    <link name="base_link">
    <visual>
        <origin xyz="0.0 0.0 0.022" rpy="0 0 0"/>
        <geometry>
            <mesh filename="package://sq2_ccv_choreonoid/meshes/base.stl" />
        </geometry>
        <material name="white">
            <color rgba="1.0 1.0 1.0 1.0"/>
        </material>
    </visual>
    <collision>
        <origin xyz="0.0 0.0 0.022" rpy="0 0 0"/>
        <geometry>
            <box size="0.105 0.501 0.044"/>
        </geometry>
    </collision>
    <inertial>
        <origin xyz="0.0 0.0 0.0" rpy="0 0 0"/>
        <mass value="5.0"/>
        <inertia ixx="0.011" ixy="0" ixz="0" iyy="0.20" iyz="0" izz="0.27"/>
    </inertial>
    </link>

    <joint name="base_link_joint" type="fixed">
    <parent link="base_footprint"/>
    <child link="base_link"/>
    <origin xyz="0 0 0" rpy="0 0 0"/>
    </joint>

<!-- base2body -->
    <link name="base2body_link">
    <visual>
        <origin xyz="0.0 0.0 0.045" rpy="0 0 0"/>
        <geometry>
            <box size="0.05 0.05 0.01"/>
        </geometry>
    </visual>
    <collision>
        <origin xyz="0.0 0.0 0.045" rpy="0 0 0"/>
        <geometry>
        <box size="0.319 0.125 0.090"/>
        </geometry>
    </collision>
    <inertial>
        <origin xyz="0.0 0.0 0.0" rpy="0 0 0"/>
        <mass value="5.0"/>
        <inertia ixx="0.011" ixy="0" ixz="0" iyy="0.20" iyz="0" izz="0.27"/>
    </inertial>
    </link>

    <joint name="base2body_link_joint" type="fixed">
    <parent link="base_link"/>
    <child link="base2body_link"/>
    <origin xyz="0 0 -0.011" rpy="0 0 0"/>
    </joint>

<!-- steering -->
    <link name="right_steering_link">
    <visual>
    <origin xyz="0 0 0" rpy="0 0 0"/>
        <geometry>
        <mesh filename="package://sq2_ccv_choreonoid/meshes/right_drive_motor.stl" />
        </geometry>
		<material name="black">
            <color rgba="0.5 0.5 0.5 1.0"/>
        </material>
    </visual>
    <collision>
		<origin xyz="0 0 0.0015" rpy="0 0 0"/>
        <geometry>
            <cylinder radius="0.01675" length="0.003"/>
        </geometry>
    </collision>
    <inertial>
		<origin xyz="0 0 0.0015" rpy="0 0 0"/>
		<mass value="1.0"/>
        <inertia ixx="0.0001" ixy="0" ixz="0" iyy="0.0001" iyz="0" izz="0.0001"/>
    </inertial>
    </link>

    <joint name="right_steering_joint" type="revolute">
    <origin xyz="0 -0.2245 0.025" rpy="0 0 0"/>
    <parent link="base_link"/>
    <child link="right_steering_link"/>
    <axis xyz="0 0 1"/>
	<limit velocity="0.010" effort="1549" lower="-0.523599" upper="0.523599"/>
    </joint>

    <link name="left_steering_link">
    <visual>
		<origin xyz="0 0 0" rpy="0 0 0"/>
        <geometry>
			<mesh filename="package://sq2_ccv_choreonoid/meshes/left_drive_motor.stl" />
        </geometry>
		<material name="black">
            <color rgba="0.5 0.5 0.5 1.0"/>
        </material>
    </visual>
    <collision>
		<origin xyz="0 0 0.0015" rpy="0 0 0"/>
        <geometry>
            <cylinder radius="0.01675" length="0.003"/>
        </geometry>
    </collision>
    <inertial>
		<origin xyz="0 0 0.0015" rpy="0 0 0"/>
		<mass value="1.0"/>
        <inertia ixx="0.0001" ixy="0" ixz="0" iyy="0.0001" iyz="0" izz="0.0001"/>
    </inertial>
    </link>

    <joint name="left_steering_joint" type="revolute">
    <origin xyz="0 0.2245 0.025" rpy="0 0 0"/>
    <parent link="base_link"/>
    <child link="left_steering_link"/>
    <axis xyz="0 0 1"/>
	<limit velocity="0.010" effort="1549" lower="-0.523599" upper="0.523599"/>
    </joint>

<!-- wheel -->
    <link name="right_wheel_link">
    <visual>
		<origin xyz="0 0 0" rpy="0 0 0"/>
        <geometry>
			<mesh filename="package://sq2_ccv_choreonoid/meshes/right_wheel.stl" />
        </geometry>
		<material name="black">
            <color rgba="0.2 0.2 0.2 1.0"/>
        </material>
    </visual>
    <collision>
		<origin xyz="0 0 0" rpy="1.5708 0 0"/>
        <geometry>
	        <cylinder radius="0.1435" length="0.025"/>
        </geometry>
    </collision>
    <inertial>
		<origin xyz="0 0 0" rpy="1.5708 0 0"/>
		<mass value="5.0"/>
        <inertia ixx="0.011" ixy="0" ixz="0" iyy="0.20" iyz="0" izz="0.27"/>
    </inertial>
    </link>

    <joint name="right_wheel_joint" type="continuous">
    <origin xyz="0 0 0.0400" rpy="0 0 0"/>
    <parent link="right_steering_link"/>
    <child link="right_wheel_link"/>
    <axis xyz="0 1 0"/>
    <limit velocity="17.45" effort="7.5"/>
    <dynamics damping="0.7"/>
    </joint>

    <link name="left_wheel_link">
    <visual>
		<origin xyz="0 0 0" rpy="0 0 0"/>
        <geometry>
			<mesh filename="package://sq2_ccv_choreonoid/meshes/left_wheel.stl" />
        </geometry>
		<material name="black">
            <color rgba="0.2 0.2 0.2 1.0"/>
        </material>
    </visual>
    <collision>
		<origin xyz="0 0 0" rpy="1.5708 0 0"/>
        <geometry>
	        <cylinder radius="0.1435" length="0.025"/>
        </geometry>
    </collision>
    <inertial>
		<origin xyz="0 0 0" rpy="1.5708 0 0"/>
		<mass value="5.0"/>
        <inertia ixx="0.011" ixy="0" ixz="0" iyy="0.20" iyz="0" izz="0.27"/>
    </inertial>
    </link>

    <joint name="left_wheel_joint" type="continuous">
    <origin xyz="0 0 0.0400" rpy="0 0 0"/>
    <parent link="left_steering_link"/>
    <child link="left_wheel_link"/>
    <axis xyz="0 1 0"/>
    <limit velocity="17.45" effort="7.5"/>
    <dynamics damping="0.7"/>
    </joint>

<!-- casters pitch -->
    <link name="front_casters_pitch_link">
    <visual>
		<origin xyz="0.0 0.0 0.0" rpy="0 0 0"/>
        <geometry>
			<mesh filename="package://sq2_ccv_choreonoid/meshes/caster2shaft.stl" />
        </geometry>
		<material name="white">
            <color rgba="1.0 1.0 1.0 1.0"/>
     	</material>
    </visual>
    <collision>
		<origin xyz="0.075 0 -0.002" rpy="0 0 0"/>
        <geometry>
    	    <!-- <box size="0.1179 0.1500 0.600"/> -->
            <box size="0.15 0.15 0.05"/>
        </geometry>
    </collision>
    <inertial>
		<origin xyz="0 0 -0.002" rpy="0 0 0"/>
        <mass value="5"/>
        <inertia ixx="1" ixy="0" ixz="0" iyz="0" iyy="1" izz="1"/>
		<mass value="1.0"/>
        <inertia ixx="0.01" ixy="0" ixz="0" iyy="0.02" iyz="0" izz="0.01"/>
    </inertial>
    </link>

    <joint name="front_casters_pitch_joint" type="revolute">
    <origin xyz="0.108 0 0.025" rpy="0 0 0"/>
    <parent link="base2body_link"/>
    <child link="front_casters_pitch_link"/>
    <axis xyz="0 1 0"/>
    <limit velocity="0.00691" effort="22436" lower="-0.3" upper="0.3"/>
    </joint>

    <link name="back_casters_pitch_link">
    <visual>
		<origin xyz="0.0 0.0 0.0" rpy="0 0 0"/>
        <geometry>
			<mesh filename="package://sq2_ccv_choreonoid/meshes/caster2shaft.stl" />
        </geometry>
		<material name="white">
            <color rgba="1.0 1.0 1.0 1.0"/>
     	</material>
    </visual>
    <collision>
		<origin xyz="0.075 0 -0.002" rpy="0 0 0"/>
        <geometry>
    	    <!-- <box size="0.1179 0.1500 0.600"/> -->
            <box size="0.15 0.15 0.05"/>
        </geometry>
    </collision>
    <inertial>
		<origin xyz="0 0 -0.002" rpy="0 0 0"/>
        <mass value="5"/>
        <inertia ixx="1" ixy="0" ixz="0" iyz="0" iyy="1" izz="1"/>
		<mass value="1.0"/>
        <inertia ixx="0.01" ixy="0" ixz="0" iyy="0.02" iyz="0" izz="0.01"/>
    </inertial>
    </link>

    <joint name="back_casters_pitch_joint" type="revolute">
    <origin xyz="-0.108 0 0.025" rpy="0 0 3.141592"/>
    <parent link="base2body_link"/>
    <child link="back_casters_pitch_link"/>
    <axis xyz="0 1 0"/>
    <limit velocity="0.00691" effort="22436" lower="-0.3" upper="0.3"/>
    </joint>

<!-- pitch to shaft -->
    <link name="front_pitch2shaft_link">
      <visual>
		<origin xyz="0.0 0 0" rpy="0 0 0"/>
        <geometry>
    	  <box size="0.078 0.120 0.04"/>
        </geometry>
        <material name="white">
           <color rgba="1.0 1.0 1.0 1.0"/>
	    </material>

      </visual>
      <collision>
		<origin xyz="0.0 0 0" rpy="0 0 0"/>
        <geometry>
    	  <box size="0.078 0.120 0.04"/>
        </geometry>
      </collision>
      <inertial>
		<origin xyz="0.0 0 0" rpy="0 0 0"/>
        <mass value="5"/>
        <inertia ixx="1" ixy="0" ixz="0" iyz="0" iyy="1" izz="1"/>
      </inertial>
    </link>

    <joint name="front_pitch2shaft_joint" type="revolute">
    <origin xyz="0.109 0 -0.0183" rpy="0 0 0"/>
    <parent link="front_casters_pitch_link"/>
    <axis xyz="1 0 0"/>
    <limit velocity="6.28" effort="28" lower="-0.5" upper="0.5"/>
	<child link="front_pitch2shaft_link"/>
    </joint>

    <link name="back_pitch2shaft_link">
      <visual>
		<origin xyz="0.0 0 0" rpy="0 0 0"/>
        <geometry>
    	  <box size="0.078 0.120 0.04"/>
        </geometry>
        <material name="white">
           <color rgba="1.0 1.0 1.0 1.0"/>
	    </material>

      </visual>
      <collision>
		<origin xyz="0.0 0 0" rpy="0 0 0"/>
        <geometry>
    	  <box size="0.078 0.120 0.04"/>
        </geometry>
      </collision>
      <inertial>
		<origin xyz="0.0 0 0" rpy="0 0 0"/>
        <mass value="5"/>
        <inertia ixx="1" ixy="0" ixz="0" iyz="0" iyy="1" izz="1"/>
      </inertial>
    </link>

    <joint name="back_pitch2shaft_joint" type="revolute">
    <origin xyz="0.109 0 -0.0183" rpy="0 0 0"/>
    <parent link="back_casters_pitch_link"/>
    <axis xyz="1 0 0"/>
    <limit velocity="6.28" effort="28" lower="-0.5" upper="0.5"/>
	<child link="back_pitch2shaft_link"/>
    </joint>

<!-- caster -->
    <link name="front_right_caster_link">
      <visual>
		<origin xyz="0 0 0" rpy="1.5708 0 0"/>
        <geometry>
	  	  <cylinder radius="0.0635" length="0.024"/>
        </geometry>
		<material name="black">
            <color rgba="0.2 0.2 0.2 1.0"/>
        </material>
      </visual>
      <collision>
		<origin xyz="0 0 0" rpy="1.5708 0 0"/>
        <geometry>
	  	  <cylinder radius="0.0635" length="0.024"/>
        </geometry>
      </collision>
      <inertial>
		<origin xyz="0 0 0" rpy="1.5708 0 0"/>
		<mass value="1.0"/>
        <inertia ixx="0.01" ixy="0" ixz="0" iyy="0.02" iyz="0" izz="0.01"/>
      </inertial>
    </link>

    <joint name="front_right_caster_joint" type="fixed">
      <origin xyz="0.043 -0.167 -0.010" rpy="0 0 0"/>
      <parent link="front_pitch2shaft_link"/>
      <child link="front_right_caster_link"/>
    </joint>

    <link name="front_left_caster_link">
      <visual>
		<origin xyz="0 0 0" rpy="1.5708 0 0"/>
        <geometry>
	  	  <cylinder radius="0.0635" length="0.024"/>
        </geometry>
		<material name="black">
            <color rgba="0.2 0.2 0.2 1.0"/>
        </material>
      </visual>
      <collision>
		<origin xyz="0 0 0" rpy="1.5708 0 0"/>
        <geometry>
	  	  <cylinder radius="0.0635" length="0.024"/>
        </geometry>
      </collision>
      <inertial>
		<origin xyz="0 0 0" rpy="1.5708 0 0"/>
		<mass value="1.0"/>
        <inertia ixx="0.01" ixy="0" ixz="0" iyy="0.02" iyz="0" izz="0.01"/>
      </inertial>
    </link>

    <joint name="front_left_caster_joint" type="fixed">
      <origin xyz="0.043 0.167 -0.010" rpy="0 0 0"/>
      <parent link="front_pitch2shaft_link"/>
      <child link="front_left_caster_link"/>
    </joint>

    <link name="back_right_caster_link">
      <visual>
		<origin xyz="0 0 0" rpy="1.5708 0 0"/>
        <geometry>
	  	  <cylinder radius="0.0635" length="0.024"/>
        </geometry>
		<material name="black">
            <color rgba="0.2 0.2 0.2 1.0"/>
        </material>
      </visual>
      <collision>
		<origin xyz="0 0 0" rpy="1.5708 0 0"/>
        <geometry>
	  	  <cylinder radius="0.0635" length="0.024"/>
        </geometry>
      </collision>
      <inertial>
		<origin xyz="0 0 0" rpy="1.5708 0 0"/>
		<mass value="1.0"/>
        <inertia ixx="0.01" ixy="0" ixz="0" iyy="0.02" iyz="0" izz="0.01"/>
      </inertial>
    </link>

    <joint name="back_right_caster_joint" type="fixed">
      <origin xyz="0.043 -0.167 -0.010" rpy="0 0 0"/>
      <parent link="back_pitch2shaft_link"/>
      <child link="back_right_caster_link"/>
    </joint>

    <link name="back_left_caster_link">
      <visual>
		<origin xyz="0 0 0" rpy="1.5708 0 0"/>
        <geometry>
	  	  <cylinder radius="0.0635" length="0.024"/>
        </geometry>
		<material name="black">
            <color rgba="0.2 0.2 0.2 1.0"/>
        </material>
      </visual>
      <collision>
		<origin xyz="0 0 0" rpy="1.5708 0 0"/>
        <geometry>
	  	  <cylinder radius="0.0635" length="0.024"/>
        </geometry>
      </collision>
      <inertial>
		<origin xyz="0 0 0" rpy="1.5708 0 0"/>
		<mass value="1.0"/>
        <inertia ixx="0.01" ixy="0" ixz="0" iyy="0.02" iyz="0" izz="0.01"/>
      </inertial>
    </link>

    <joint name="back_left_caster_joint" type="fixed">
      <origin xyz="0.043 0.167 -0.010" rpy="0 0 0"/>
      <parent link="back_pitch2shaft_link"/>
      <child link="back_left_caster_link"/>
    </joint>

<!-- caster cover -->
    <link name="front_caster_cover_link">
      <visual>
        <origin xyz="0.0 0.0 0.022" rpy="0 0 0"/>
        <geometry>
			<mesh filename="package://sq2_ccv_choreonoid/meshes/front_caster_cover.stl" />
        </geometry>
		<material name="white">
           <color rgba="1.0 1.0 1.0 1.0"/>
        </material>
      </visual>
    </link>

    <joint name="front_caster_cover_link_joint" type="fixed">
      <origin xyz="-0.2124 0.00 0.00" rpy="0 0 0"/>
      <parent link="front_pitch2shaft_link"/>
      <child link="front_caster_cover_link"/>
    </joint>

    <link name="back_caster_cover_link">
      <visual>
        <origin xyz="0.0 0.0 0.022" rpy="0 0 0"/>
        <geometry>
			<mesh filename="package://sq2_ccv_choreonoid/meshes/back_caster_cover.stl" />
        </geometry>
		<material name="white">
            <color rgba="1.0 1.0 1.0 1.0"/>
        </material>
      </visual>
    </link>

    <joint name="back_caster_cover_link_joint" type="fixed">
    <origin xyz="-0.2124 0.00 0.00" rpy="0 0 3.141592"/>
    <parent link="back_pitch2shaft_link"/>
    <child link="back_caster_cover_link"/>
    </joint>


    <!-- ########## -->
    <!-- upper body -->
    <!-- ########## -->

<!-- battery box -->
    <link name="battery_box_link">
    <visual>
		<origin xyz="0 0 0" rpy="0 0 0"/>
        <geometry>
			<mesh filename="package://sq2_ccv_choreonoid/meshes/roll_joint.stl" />
        </geometry>
		<material name="black">
            <color rgba="0.0 0.0 0.0 1.0"/>
         </material>
    </visual>
    <collision>
		<origin xyz="0 0 0.24675" rpy="0 0 0"/>
        <geometry>
    	<box size="0.208 0.208 0.5535"/>
        </geometry>
    </collision>
    <inertial>
	    <origin xyz="0 0 0.25" rpy="0 0 0"/>
		<mass value="10"/>
        <inertia ixx="1" ixy="0" ixz="0" iyz="0" iyy="1" izz="1"/>
    </inertial>
    </link>

    <joint name="battery_box_joint" type="revolute">
    <origin xyz="0 0 0.061" rpy="0 0 0"/>
    <parent link="base2body_link"/>
    <axis xyz="1 0 0"/>
	<limit velocity="1" effort="1000" lower="-0.523599" upper="0.523599"/>
	<limit velocity="0.00691" effort="22436" lower="-0.523599" upper="0.523599"/>
	<child link="battery_box_link"/>
    </joint>

<!-- upper body -->
    <link name="upper_body_link">
      <visual>
		<origin xyz="0.0 0.0 0.0" rpy="0 0 0"/>
        <geometry>
			<mesh filename="package://sq2_ccv_choreonoid/meshes/body.stl" />
        </geometry>
      </visual>
      <collision>
		  <origin xyz="0.0 0.0 0.254" rpy="0 0 0"/>
        <geometry>
		  <box size="0.258 0.258 0.508"/>
        </geometry>
      </collision>
      <inertial>
		  <origin xyz="0.0 0.0 0.254" rpy="0 0 0"/>
		  <mass value="20"/>
        <inertia ixx="1" ixy="0" ixz="0" iyz="0" iyy="1" izz="1"/>
      </inertial>
    </link>

    <joint name="upper_body_link_joint" type="fixed">
    <origin xyz="0 0 0.100" rpy="0 0 0"/>
      <parent link="battery_box_link"/>
      <child link="upper_body_link"/>
    </joint>

<!-- upper cover -->
    <link name="upper_cover_link">
      <visual>
        <origin xyz="0.0 0.0 0.0" rpy="0 0 0"/>
        <geometry>
			<mesh filename="package://sq2_ccv_choreonoid/meshes/upper_cover.stl" />
        </geometry>
		<material name="white">
             <color rgba="1.0 1.0 1.0 1.0"/>
		</material>
      </visual>
    </link>

    <joint name="upper_cover_link_joint" type="fixed">
      <origin xyz="0 0 -0.028" rpy="0 0 0"/>
      <parent link="battery_box_link"/>
      <child link="upper_cover_link"/>
    </joint>

<!-- lidar pillar -->
    <link name="lidar_pillar_link">
      <visual>
		<origin xyz="0.0 0.0 0.00005" rpy="0 0 0"/>
        <geometry>
		  <box size="0.145 0.145 0.0001"/>
        </geometry>
      </visual>
      <collision>
		<origin xyz="0.0 0.0 0.00005" rpy="0 0 0"/>
        <geometry>
		  <box size="0.145 0.145 0.0001"/>
        </geometry>
      </collision>
      <inertial>
		  <origin xyz="0.0 0.0 0.00005" rpy="0 0 0"/>
        <mass value="5"/>
        <inertia ixx="1" ixy="0" ixz="0" iyz="0" iyy="1" izz="1"/>
      </inertial>
    </link>

    <joint name="lidar_pillar_link_joint" type="fixed">
      <origin xyz="0 0 0.0" rpy="0 0 0"/>
      <parent link="upper_body_link"/>
      <child link="lidar_pillar_link"/>
    </joint>


    <!-- transmission -->
    <transmission name="right_steering_trans">
      <type>transmission_interface/SimpleTransmission</type>
      <joint name="right_steering_joint">
        <hardwareInterface>hardware_interface/PositionJointInterface</hardwareInterface>
      </joint>
      <actuator name="right_steering_motor">
        <hardwareInterface>hardware_interface/PositionJointInterface</hardwareInterface>
        <mechanicalReduction>30</mechanicalReduction>
      </actuator>
    </transmission>

    <transmission name="left_steering_trans">
      <type>transmission_interface/SimpleTransmission</type>
      <joint name="left_steering_joint">
        <hardwareInterface>hardware_interface/PositionJointInterface</hardwareInterface>
      </joint>
      <actuator name="left_steering_motor">
        <hardwareInterface>hardware_interface/PositionJointInterface</hardwareInterface>
        <mechanicalReduction>30</mechanicalReduction>
      </actuator>
    </transmission>

    <transmission name="right_wheel_trans">
      <type>transmission_interface/SimpleTransmission</type>
      <joint name="right_wheel_joint">
        <hardwareInterface>hardware_interface/VelocityJointInterface</hardwareInterface>
      </joint>
      <actuator name="right_wheel_motor">
        <hardwareInterface>hardware_interface/VelocityJointInterface</hardwareInterface>
        <mechanicalReduction>30</mechanicalReduction>
      </actuator>
    </transmission>

    <transmission name="left_wheel_trans">
      <type>transmission_interface/SimpleTransmission</type>
      <joint name="left_wheel_joint">
        <hardwareInterface>hardware_interface/VelocityJointInterface</hardwareInterface>
      </joint>
      <actuator name="left_wheel_motor">
        <hardwareInterface>hardware_interface/VelocityJointInterface</hardwareInterface>
        <mechanicalReduction>30</mechanicalReduction>
      </actuator>
    </transmission>

    <transmission name="front_casters_pitch_trans">
      <type>transmission_interface/SimpleTransmission</type>
      <joint name="front_casters_pitch_joint">
        <hardwareInterface>hardware_interface/PositionJointInterface</hardwareInterface>
      </joint>
      <actuator name="front_casters_pitch_motor">
        <hardwareInterface>hardware_interface/PositionJointInterface</hardwareInterface>
        <mechanicalReduction>30</mechanicalReduction>
      </actuator>
    </transmission>

    <transmission name="back_casters_pitch_trans">
      <type>transmission_interface/SimpleTransmission</type>
      <joint name="back_casters_pitch_joint">
        <hardwareInterface>hardware_interface/PositionJointInterface</hardwareInterface>
      </joint>
      <actuator name="back_casters_pitch_motor">
        <hardwareInterface>hardware_interface/PositionJointInterface</hardwareInterface>
        <mechanicalReduction>30</mechanicalReduction>
      </actuator>
    </transmission>

    <transmission name="battery_box_trans">
      <type>transmission_interface/SimpleTransmission</type>
      <joint name="battery_box_joint">
        <hardwareInterface>hardware_interface/PositionJointInterface</hardwareInterface>
      </joint>
      <actuator name="battery_box_motor">
        <hardwareInterface>hardware_interface/PositionJointInterface</hardwareInterface>
        <mechanicalReduction>30</mechanicalReduction>
      </actuator>
    </transmission>



</robot>