<?xml version="1.0"?>
<robot xmlns:xacro="http://ros.org/wiki/xacro">

    <xacro:include filename="$(find sq2_ccv_choreonoid)/xacro/common.xacro"/>

    <xacro:property name="wheel_radius" value="0.1435"/>
    <xacro:property name="wheel_width" value="0.0415"/>
    <xacro:property name="wheel_mass" value="5.0"/>

    <xacro:macro name="wheel" params="prefix parent *joint_origin">
        <joint name="${prefix}_wheel_joint" type="continuous">
            <xacro:insert_block name="joint_origin"/>
            <parent link="${parent}"/>
            <child link="${prefix}_wheel_link"/>
            <axis xyz="0 1 0"/>
        </joint>

        <link name="${prefix}_wheel_link">
            <visual>
                <origin xyz="0 0 0" rpy="0 0 0"/>
                <material name="black"/>
                <color rgba="0.2 0.2 0.2 1"/>
                <geometry>
                    <mesh filename="package://sq2_ccv_choreonoid/meshes/${prefix}_wheel.stl" />
                </geometry>
            </visual>
            <collision>
                <origin xyz="0 0 0" rpy="0 0 0"/>
                <geometry>
                    <cylinder radius="${wheel_radius}" length="${wheel_width}"/>
                </geometry>
            </collision>
            <inertial>
                <origin xyz="0 0 0" rpy="0 0 0"/>
                <xacro:cylinder_inertial mass="${wheel_mass}" radius="${wheel_radius}" length="${wheel_width}"/>
            </inertial>
        </link>

        <gazebo reference="${prefix}_wheel_link">
            <selfCollide>false</selfCollide>
            <mu1 value="0.8"/>
            <mu2 value="0.8"/>
        </gazebo>
    </xacro:macro>
</robot>
